done!
done!
done!
done!
Traceback (most recent call last):
  File "/home/nvdia/kernel_panic/core/spyder/scripts/logger.py", line 31, in <module>
    if out.find("/usr/bin/python") == -1 and not r.get("USER_PROMPTED"):
  File "/usr/local/lib/python2.7/dist-packages/redis/client.py", line 616, in get
    return self.execute_command('GET', name)
  File "/usr/local/lib/python2.7/dist-packages/redis/client.py", line 397, in execute_command
    connection.send_command(*args)
  File "/usr/local/lib/python2.7/dist-packages/redis/connection.py", line 306, in send_command
    self.send_packed_command(self.pack_command(*args))
  File "/usr/local/lib/python2.7/dist-packages/redis/connection.py", line 288, in send_packed_command
    self.connect()
  File "/usr/local/lib/python2.7/dist-packages/redis/connection.py", line 235, in connect
    raise ConnectionError(self._error_message(e))
redis.exceptions.ConnectionError: Error 111 connecting localhost:6379. Connection refused.
